INFO 2024-09-25 21:59:34,202 autoreload 128 5516 Watching for file changes with StatReloader
INFO 2024-09-25 22:07:45,289 autoreload 2528 132 Watching for file changes with StatReloader
INFO 2024-09-25 22:37:54,612 autoreload 12928 1760 Watching for file changes with StatReloader
INFO 2024-09-25 23:02:49,651 autoreload 1452 15592 Watching for file changes with StatReloader
ERROR 2024-09-25 23:12:02,854 log 1452 10020 Internal Server Error: /
Traceback (most recent call last):
  File "C:\Django\Final certification\djangoRecipeSite\.venv\Lib\site-packages\django\db\backends\utils.py", line 105, in _execute
    return self.cursor.execute(sql, params)
           ^^^^^^^^^^^^^^^^^^^^^^^^^^^^^^^^
  File "C:\Django\Final certification\djangoRecipeSite\.venv\Lib\site-packages\django\db\backends\sqlite3\base.py", line 354, in execute
    return super().execute(query, params)
           ^^^^^^^^^^^^^^^^^^^^^^^^^^^^^^
sqlite3.OperationalError: no such table: recipeSiteapp_recipe

The above exception was the direct cause of the following exception:

Traceback (most recent call last):
  File "C:\Django\Final certification\djangoRecipeSite\.venv\Lib\site-packages\django\core\handlers\exception.py", line 55, in inner
    response = get_response(request)
               ^^^^^^^^^^^^^^^^^^^^^
  File "C:\Django\Final certification\djangoRecipeSite\.venv\Lib\site-packages\django\core\handlers\base.py", line 197, in _get_response
    response = wrapped_callback(request, *callback_args, **callback_kwargs)
               ^^^^^^^^^^^^^^^^^^^^^^^^^^^^^^^^^^^^^^^^^^^^^^^^^^^^^^^^^^^^
  File "C:\Django\Final certification\djangoRecipeSite\recipeSite\recipeSiteapp\views.py", line 18, in wrapper
    res = f(*args, **kwargs)
          ^^^^^^^^^^^^^^^^^^
  File "C:\Django\Final certification\djangoRecipeSite\recipeSite\recipeSiteapp\views.py", line 36, in index
    count = Recipe.objects.filter(is_visible=True).count()
            ^^^^^^^^^^^^^^^^^^^^^^^^^^^^^^^^^^^^^^^^^^^^^^
  File "C:\Django\Final certification\djangoRecipeSite\.venv\Lib\site-packages\django\db\models\query.py", line 620, in count
    return self.query.get_count(using=self.db)
           ^^^^^^^^^^^^^^^^^^^^^^^^^^^^^^^^^^^
  File "C:\Django\Final certification\djangoRecipeSite\.venv\Lib\site-packages\django\db\models\sql\query.py", line 630, in get_count
    return obj.get_aggregation(using, {"__count": Count("*")})["__count"]
           ^^^^^^^^^^^^^^^^^^^^^^^^^^^^^^^^^^^^^^^^^^^^^^^^^^^
  File "C:\Django\Final certification\djangoRecipeSite\.venv\Lib\site-packages\django\db\models\sql\query.py", line 616, in get_aggregation
    result = compiler.execute_sql(SINGLE)
             ^^^^^^^^^^^^^^^^^^^^^^^^^^^^
  File "C:\Django\Final certification\djangoRecipeSite\.venv\Lib\site-packages\django\db\models\sql\compiler.py", line 1574, in execute_sql
    cursor.execute(sql, params)
  File "C:\Django\Final certification\djangoRecipeSite\.venv\Lib\site-packages\django\db\backends\utils.py", line 122, in execute
    return super().execute(sql, params)
           ^^^^^^^^^^^^^^^^^^^^^^^^^^^^
  File "C:\Django\Final certification\djangoRecipeSite\.venv\Lib\site-packages\django\db\backends\utils.py", line 79, in execute
    return self._execute_with_wrappers(
           ^^^^^^^^^^^^^^^^^^^^^^^^^^^^
  File "C:\Django\Final certification\djangoRecipeSite\.venv\Lib\site-packages\django\db\backends\utils.py", line 92, in _execute_with_wrappers
    return executor(sql, params, many, context)
           ^^^^^^^^^^^^^^^^^^^^^^^^^^^^^^^^^^^^
  File "C:\Django\Final certification\djangoRecipeSite\.venv\Lib\site-packages\django\db\backends\utils.py", line 100, in _execute
    with self.db.wrap_database_errors:
  File "C:\Django\Final certification\djangoRecipeSite\.venv\Lib\site-packages\django\db\utils.py", line 91, in __exit__
    raise dj_exc_value.with_traceback(traceback) from exc_value
  File "C:\Django\Final certification\djangoRecipeSite\.venv\Lib\site-packages\django\db\backends\utils.py", line 105, in _execute
    return self.cursor.execute(sql, params)
           ^^^^^^^^^^^^^^^^^^^^^^^^^^^^^^^^
  File "C:\Django\Final certification\djangoRecipeSite\.venv\Lib\site-packages\django\db\backends\sqlite3\base.py", line 354, in execute
    return super().execute(query, params)
           ^^^^^^^^^^^^^^^^^^^^^^^^^^^^^^
django.db.utils.OperationalError: no such table: recipeSiteapp_recipe
ERROR 2024-09-25 23:12:02,872 basehttp 1452 10020 "GET / HTTP/1.1" 500 133690
WARNING 2024-09-25 23:12:03,476 log 1452 10020 Not Found: /favicon.ico
WARNING 2024-09-25 23:12:03,477 basehttp 1452 10020 "GET /favicon.ico HTTP/1.1" 404 4602
WARNING 2024-09-25 23:12:25,579 log 1452 10020 Not Found: /about/
WARNING 2024-09-25 23:12:25,581 basehttp 1452 10020 "GET /about/ HTTP/1.1" 404 4587
INFO 2024-09-25 23:12:27,096 basehttp 1452 10020 "GET /admin HTTP/1.1" 301 0
ERROR 2024-09-25 23:12:27,269 log 1452 11024 Internal Server Error: /admin/
Traceback (most recent call last):
  File "C:\Django\Final certification\djangoRecipeSite\.venv\Lib\site-packages\django\contrib\sessions\backends\base.py", line 244, in _get_session
    return self._session_cache
           ^^^^^^^^^^^^^^^^^^^
AttributeError: 'SessionStore' object has no attribute '_session_cache'

During handling of the above exception, another exception occurred:

Traceback (most recent call last):
  File "C:\Django\Final certification\djangoRecipeSite\.venv\Lib\site-packages\django\db\backends\utils.py", line 105, in _execute
    return self.cursor.execute(sql, params)
           ^^^^^^^^^^^^^^^^^^^^^^^^^^^^^^^^
  File "C:\Django\Final certification\djangoRecipeSite\.venv\Lib\site-packages\django\db\backends\sqlite3\base.py", line 354, in execute
    return super().execute(query, params)
           ^^^^^^^^^^^^^^^^^^^^^^^^^^^^^^
sqlite3.OperationalError: no such table: django_session

The above exception was the direct cause of the following exception:

Traceback (most recent call last):
  File "C:\Django\Final certification\djangoRecipeSite\.venv\Lib\site-packages\django\core\handlers\exception.py", line 55, in inner
    response = get_response(request)
               ^^^^^^^^^^^^^^^^^^^^^
  File "C:\Django\Final certification\djangoRecipeSite\.venv\Lib\site-packages\django\core\handlers\base.py", line 197, in _get_response
    response = wrapped_callback(request, *callback_args, **callback_kwargs)
               ^^^^^^^^^^^^^^^^^^^^^^^^^^^^^^^^^^^^^^^^^^^^^^^^^^^^^^^^^^^^
  File "C:\Django\Final certification\djangoRecipeSite\.venv\Lib\site-packages\django\contrib\admin\sites.py", line 260, in wrapper
    return self.admin_view(view, cacheable)(*args, **kwargs)
           ^^^^^^^^^^^^^^^^^^^^^^^^^^^^^^^^^^^^^^^^^^^^^^^^^
  File "C:\Django\Final certification\djangoRecipeSite\.venv\Lib\site-packages\django\utils\decorators.py", line 188, in _view_wrapper
    result = _process_exception(request, e)
             ^^^^^^^^^^^^^^^^^^^^^^^^^^^^^^
  File "C:\Django\Final certification\djangoRecipeSite\.venv\Lib\site-packages\django\utils\decorators.py", line 186, in _view_wrapper
    response = view_func(request, *args, **kwargs)
               ^^^^^^^^^^^^^^^^^^^^^^^^^^^^^^^^^^^
  File "C:\Django\Final certification\djangoRecipeSite\.venv\Lib\site-packages\django\views\decorators\cache.py", line 80, in _view_wrapper
    response = view_func(request, *args, **kwargs)
               ^^^^^^^^^^^^^^^^^^^^^^^^^^^^^^^^^^^
  File "C:\Django\Final certification\djangoRecipeSite\.venv\Lib\site-packages\django\contrib\admin\sites.py", line 229, in inner
    if not self.has_permission(request):
           ^^^^^^^^^^^^^^^^^^^^^^^^^^^^
  File "C:\Django\Final certification\djangoRecipeSite\.venv\Lib\site-packages\django\contrib\admin\sites.py", line 202, in has_permission
    return request.user.is_active and request.user.is_staff
           ^^^^^^^^^^^^^^^^^^^^^^
  File "C:\Django\Final certification\djangoRecipeSite\.venv\Lib\site-packages\django\utils\functional.py", line 251, in inner
    self._setup()
  File "C:\Django\Final certification\djangoRecipeSite\.venv\Lib\site-packages\django\utils\functional.py", line 404, in _setup
    self._wrapped = self._setupfunc()
                    ^^^^^^^^^^^^^^^^^
  File "C:\Django\Final certification\djangoRecipeSite\.venv\Lib\site-packages\django\contrib\auth\middleware.py", line 37, in <lambda>
    request.user = SimpleLazyObject(lambda: get_user(request))
                                            ^^^^^^^^^^^^^^^^^
  File "C:\Django\Final certification\djangoRecipeSite\.venv\Lib\site-packages\django\contrib\auth\middleware.py", line 17, in get_user
    request._cached_user = auth.get_user(request)
                           ^^^^^^^^^^^^^^^^^^^^^^
  File "C:\Django\Final certification\djangoRecipeSite\.venv\Lib\site-packages\django\contrib\auth\__init__.py", line 209, in get_user
    user_id = _get_user_session_key(request)
              ^^^^^^^^^^^^^^^^^^^^^^^^^^^^^^
  File "C:\Django\Final certification\djangoRecipeSite\.venv\Lib\site-packages\django\contrib\auth\__init__.py", line 62, in _get_user_session_key
    return get_user_model()._meta.pk.to_python(request.session[SESSION_KEY])
                                               ~~~~~~~~~~~~~~~^^^^^^^^^^^^^
  File "C:\Django\Final certification\djangoRecipeSite\.venv\Lib\site-packages\django\contrib\sessions\backends\base.py", line 55, in __getitem__
    return self._session[key]
           ^^^^^^^^^^^^^
  File "C:\Django\Final certification\djangoRecipeSite\.venv\Lib\site-packages\django\contrib\sessions\backends\base.py", line 249, in _get_session
    self._session_cache = self.load()
                          ^^^^^^^^^^^
  File "C:\Django\Final certification\djangoRecipeSite\.venv\Lib\site-packages\django\contrib\sessions\backends\db.py", line 55, in load
    s = self._get_session_from_db()
        ^^^^^^^^^^^^^^^^^^^^^^^^^^^
  File "C:\Django\Final certification\djangoRecipeSite\.venv\Lib\site-packages\django\contrib\sessions\backends\db.py", line 34, in _get_session_from_db
    return self.model.objects.get(
           ^^^^^^^^^^^^^^^^^^^^^^^
  File "C:\Django\Final certification\djangoRecipeSite\.venv\Lib\site-packages\django\db\models\manager.py", line 87, in manager_method
    return getattr(self.get_queryset(), name)(*args, **kwargs)
           ^^^^^^^^^^^^^^^^^^^^^^^^^^^^^^^^^^^^^^^^^^^^^^^^^^^
  File "C:\Django\Final certification\djangoRecipeSite\.venv\Lib\site-packages\django\db\models\query.py", line 645, in get
    num = len(clone)
          ^^^^^^^^^^
  File "C:\Django\Final certification\djangoRecipeSite\.venv\Lib\site-packages\django\db\models\query.py", line 382, in __len__
    self._fetch_all()
  File "C:\Django\Final certification\djangoRecipeSite\.venv\Lib\site-packages\django\db\models\query.py", line 1928, in _fetch_all
    self._result_cache = list(self._iterable_class(self))
                         ^^^^^^^^^^^^^^^^^^^^^^^^^^^^^^^^
  File "C:\Django\Final certification\djangoRecipeSite\.venv\Lib\site-packages\django\db\models\query.py", line 91, in __iter__
    results = compiler.execute_sql(
              ^^^^^^^^^^^^^^^^^^^^^
  File "C:\Django\Final certification\djangoRecipeSite\.venv\Lib\site-packages\django\db\models\sql\compiler.py", line 1574, in execute_sql
    cursor.execute(sql, params)
  File "C:\Django\Final certification\djangoRecipeSite\.venv\Lib\site-packages\django\db\backends\utils.py", line 122, in execute
    return super().execute(sql, params)
           ^^^^^^^^^^^^^^^^^^^^^^^^^^^^
  File "C:\Django\Final certification\djangoRecipeSite\.venv\Lib\site-packages\django\db\backends\utils.py", line 79, in execute
    return self._execute_with_wrappers(
           ^^^^^^^^^^^^^^^^^^^^^^^^^^^^
  File "C:\Django\Final certification\djangoRecipeSite\.venv\Lib\site-packages\django\db\backends\utils.py", line 92, in _execute_with_wrappers
    return executor(sql, params, many, context)
           ^^^^^^^^^^^^^^^^^^^^^^^^^^^^^^^^^^^^
  File "C:\Django\Final certification\djangoRecipeSite\.venv\Lib\site-packages\django\db\backends\utils.py", line 100, in _execute
    with self.db.wrap_database_errors:
  File "C:\Django\Final certification\djangoRecipeSite\.venv\Lib\site-packages\django\db\utils.py", line 91, in __exit__
    raise dj_exc_value.with_traceback(traceback) from exc_value
  File "C:\Django\Final certification\djangoRecipeSite\.venv\Lib\site-packages\django\db\backends\utils.py", line 105, in _execute
    return self.cursor.execute(sql, params)
           ^^^^^^^^^^^^^^^^^^^^^^^^^^^^^^^^
  File "C:\Django\Final certification\djangoRecipeSite\.venv\Lib\site-packages\django\db\backends\sqlite3\base.py", line 354, in execute
    return super().execute(query, params)
           ^^^^^^^^^^^^^^^^^^^^^^^^^^^^^^
django.db.utils.OperationalError: no such table: django_session
ERROR 2024-09-25 23:12:27,291 basehttp 1452 11024 "GET /admin/ HTTP/1.1" 500 206228
INFO 2024-09-27 22:17:43,721 autoreload 4408 3240 Watching for file changes with StatReloader
INFO 2024-09-27 22:33:42,801 autoreload 12448 4444 Watching for file changes with StatReloader
INFO 2024-09-27 22:34:38,365 autoreload 15208 12644 Watching for file changes with StatReloader
INFO 2024-09-27 23:08:19,288 autoreload 1028 2576 Watching for file changes with StatReloader
INFO 2024-09-27 23:13:01,703 autoreload 2384 8472 Watching for file changes with StatReloader
INFO 2024-09-27 23:15:57,023 autoreload 11384 13764 Watching for file changes with StatReloader
INFO 2024-09-27 23:28:32,172 autoreload 8024 10344 Watching for file changes with StatReloader
INFO 2024-09-28 19:40:32,117 autoreload 11616 4292 Watching for file changes with StatReloader
INFO 2024-09-28 19:55:15,128 autoreload 11616 4292 C:\Django\Final certification\djangoRecipeSite\recipeSite\recipeSite\settings.py changed, reloading.
INFO 2024-09-28 19:55:25,209 autoreload 15036 6072 Watching for file changes with StatReloader
INFO 2024-09-28 19:55:43,088 autoreload 13936 17048 Watching for file changes with StatReloader
INFO 2024-09-28 20:14:39,244 autoreload 5228 488 Watching for file changes with StatReloader
INFO 2024-09-28 20:27:22,313 autoreload 11868 12628 Watching for file changes with StatReloader
INFO 2024-09-28 20:27:43,394 autoreload 11868 12628 C:\Django\Final certification\djangoRecipeSite\recipeSite\recipeSiteapp\urls.py changed, reloading.
INFO 2024-09-28 20:27:45,275 autoreload 8556 1352 Watching for file changes with StatReloader
INFO 2024-09-28 20:47:53,361 autoreload 8556 1352 C:\Django\Final certification\djangoRecipeSite\recipeSite\recipeSite\settings.py changed, reloading.
INFO 2024-09-28 20:47:55,113 autoreload 9036 12124 Watching for file changes with StatReloader
INFO 2024-09-28 20:56:06,375 autoreload 9036 12124 C:\Django\Final certification\djangoRecipeSite\recipeSite\recipeSiteapp\urls.py changed, reloading.
INFO 2024-09-28 20:56:08,083 autoreload 10420 2536 Watching for file changes with StatReloader
INFO 2024-09-28 21:27:58,542 autoreload 12756 14344 Watching for file changes with StatReloader
INFO 2024-09-28 21:32:45,913 autoreload 4980 2484 Watching for file changes with StatReloader
INFO 2024-09-29 21:20:20,537 autoreload 12528 17092 Watching for file changes with StatReloader
INFO 2024-09-29 21:35:46,645 autoreload 11632 9440 Watching for file changes with StatReloader
INFO 2024-10-01 20:27:28,118 autoreload 7028 10988 Watching for file changes with StatReloader
INFO 2024-10-01 21:17:13,408 autoreload 7028 10988 C:\Django\Final certification\djangoRecipeSite\recipeSite\recipeSite\settings.py changed, reloading.
INFO 2024-10-01 21:17:15,640 autoreload 16760 11096 Watching for file changes with StatReloader
INFO 2024-10-01 21:18:24,278 autoreload 16760 11096 C:\Django\Final certification\djangoRecipeSite\recipeSite\recipeSite\settings.py changed, reloading.
